<?xml version="1.0" encoding="UTF-8"?>
<!-- Generated by org.testng.reporters.JUnitXMLReporter -->
<testsuite ignored="0" hostname="Harneets-MacBook-Pro.local" failures="1" tests="1" name="Default test" time="10.382" errors="0" timestamp="2023-12-08T12:38:15 EST">
  <testcase classname="com.docker.FirefoxTest" name="test2" time="10.359">
    <failure type="org.openqa.selenium.SessionNotCreatedException" message="Could not start a new session. Possible causes are invalid address of the remote server or browser start-up failure. 
Host info: host: &amp;apos;Harneets-MacBook-Pro.local&amp;apos;, ip: &amp;apos;fe80:0:0:0:1ca8:ed67:7e8b:71c3%en0&amp;apos;
Build info: version: &amp;apos;4.12.1&amp;apos;, revision: &amp;apos;8e34639b11&amp;apos;
System info: os.name: &amp;apos;Mac OS X&amp;apos;, os.arch: &amp;apos;aarch64&amp;apos;, os.version: &amp;apos;14.1.1&amp;apos;, java.version: &amp;apos;17.0.1&amp;apos;
Driver info: org.openqa.selenium.remote.RemoteWebDriver
Command: [null, newSession {capabilities=[Capabilities {browserName: firefox}]}]
Capabilities {browserName: firefox}">
      <![CDATA[org.openqa.selenium.SessionNotCreatedException: Could not start a new session. Possible causes are invalid address of the remote server or browser start-up failure. 
Host info: host: 'Harneets-MacBook-Pro.local', ip: 'fe80:0:0:0:1ca8:ed67:7e8b:71c3%en0'
Build info: version: '4.12.1', revision: '8e34639b11'
System info: os.name: 'Mac OS X', os.arch: 'aarch64', os.version: '14.1.1', java.version: '17.0.1'
Driver info: org.openqa.selenium.remote.RemoteWebDriver
Command: [null, newSession {capabilities=[Capabilities {browserName: firefox}]}]
Capabilities {browserName: firefox}
at org.openqa.selenium.remote.RemoteWebDriver.execute(RemoteWebDriver.java:620)
at org.openqa.selenium.remote.RemoteWebDriver.startSession(RemoteWebDriver.java:236)
at org.openqa.selenium.remote.RemoteWebDriver.<init>(RemoteWebDriver.java:163)
at org.openqa.selenium.remote.RemoteWebDriver.<init>(RemoteWebDriver.java:143)
at com.docker.FirefoxTest.test2(FirefoxTest.java:29)
at java.base/jdk.internal.reflect.NativeMethodAccessorImpl.invoke0(Native Method)
at java.base/jdk.internal.reflect.NativeMethodAccessorImpl.invoke(NativeMethodAccessorImpl.java:77)
at java.base/jdk.internal.reflect.DelegatingMethodAccessorImpl.invoke(DelegatingMethodAccessorImpl.java:43)
at java.base/java.lang.reflect.Method.invoke(Method.java:568)
at org.testng.internal.invokers.MethodInvocationHelper.invokeMethod(MethodInvocationHelper.java:139)
at org.testng.internal.invokers.TestInvoker.invokeMethod(TestInvoker.java:677)
at org.testng.internal.invokers.TestInvoker.invokeTestMethod(TestInvoker.java:221)
at org.testng.internal.invokers.MethodRunner.runInSequence(MethodRunner.java:50)
at org.testng.internal.invokers.TestInvoker$MethodInvocationAgent.invoke(TestInvoker.java:969)
at org.testng.internal.invokers.TestInvoker.invokeTestMethods(TestInvoker.java:194)
at org.testng.internal.invokers.TestMethodWorker.invokeTestMethods(TestMethodWorker.java:148)
at org.testng.internal.invokers.TestMethodWorker.run(TestMethodWorker.java:128)
at java.base/java.util.ArrayList.forEach(ArrayList.java:1511)
at org.testng.TestRunner.privateRun(TestRunner.java:829)
at org.testng.TestRunner.run(TestRunner.java:602)
at org.testng.SuiteRunner.runTest(SuiteRunner.java:437)
at org.testng.SuiteRunner.runSequentially(SuiteRunner.java:431)
at org.testng.SuiteRunner.privateRun(SuiteRunner.java:391)
at org.testng.SuiteRunner.run(SuiteRunner.java:330)
at org.testng.SuiteRunnerWorker.runSuite(SuiteRunnerWorker.java:52)
at org.testng.SuiteRunnerWorker.run(SuiteRunnerWorker.java:95)
at org.testng.TestNG.runSuitesSequentially(TestNG.java:1256)
at org.testng.TestNG.runSuitesLocally(TestNG.java:1176)
at org.testng.TestNG.runSuites(TestNG.java:1099)
at org.testng.TestNG.run(TestNG.java:1067)
at org.testng.remote.AbstractRemoteTestNG.run(AbstractRemoteTestNG.java:115)
at org.testng.remote.RemoteTestNG.initAndRun(RemoteTestNG.java:251)
at org.testng.remote.RemoteTestNG.main(RemoteTestNG.java:77)
Caused by: java.io.UncheckedIOException: java.net.ConnectException: connection timed out: /192.168.0.244:4444
at org.openqa.selenium.remote.http.netty.NettyHttpHandler.makeCall(NettyHttpHandler.java:73)
at org.openqa.selenium.remote.http.AddSeleniumUserAgent.lambda$apply$0(AddSeleniumUserAgent.java:42)
at org.openqa.selenium.remote.http.Filter.lambda$andFinally$1(Filter.java:55)
at org.openqa.selenium.remote.http.netty.NettyHttpHandler.execute(NettyHttpHandler.java:48)
at org.openqa.selenium.remote.http.netty.NettyClient.execute(NettyClient.java:96)
at org.openqa.selenium.remote.tracing.TracedHttpClient.execute(TracedHttpClient.java:54)
at org.openqa.selenium.remote.ProtocolHandshake.createSession(ProtocolHandshake.java:115)
at org.openqa.selenium.remote.ProtocolHandshake.createSession(ProtocolHandshake.java:96)
at org.openqa.selenium.remote.ProtocolHandshake.createSession(ProtocolHandshake.java:68)
at org.openqa.selenium.remote.HttpCommandExecutor.execute(HttpCommandExecutor.java:163)
at org.openqa.selenium.remote.TracedCommandExecutor.execute(TracedCommandExecutor.java:51)
at org.openqa.selenium.remote.RemoteWebDriver.execute(RemoteWebDriver.java:602)
... 32 more
Caused by: java.net.ConnectException: connection timed out: /192.168.0.244:4444
at org.asynchttpclient.netty.channel.NettyConnectListener.onFailure(NettyConnectListener.java:179)
at org.asynchttpclient.netty.channel.NettyChannelConnector$1.onFailure(NettyChannelConnector.java:108)
at org.asynchttpclient.netty.SimpleChannelFutureListener.operationComplete(SimpleChannelFutureListener.java:28)
at org.asynchttpclient.netty.SimpleChannelFutureListener.operationComplete(SimpleChannelFutureListener.java:20)
at io.netty.util.concurrent.DefaultPromise.notifyListener0(DefaultPromise.java:590)
at io.netty.util.concurrent.DefaultPromise.notifyListeners0(DefaultPromise.java:583)
at io.netty.util.concurrent.DefaultPromise.notifyListenersNow(DefaultPromise.java:559)
at io.netty.util.concurrent.DefaultPromise.notifyListeners(DefaultPromise.java:492)
at io.netty.util.concurrent.DefaultPromise.setValue0(DefaultPromise.java:636)
at io.netty.util.concurrent.DefaultPromise.setFailure0(DefaultPromise.java:629)
at io.netty.util.concurrent.DefaultPromise.tryFailure(DefaultPromise.java:118)
at io.netty.channel.nio.AbstractNioChannel$AbstractNioUnsafe$1.run(AbstractNioChannel.java:262)
at io.netty.util.concurrent.PromiseTask.runTask(PromiseTask.java:98)
at io.netty.util.concurrent.ScheduledFutureTask.run(ScheduledFutureTask.java:153)
at io.netty.util.concurrent.AbstractEventExecutor.runTask(AbstractEventExecutor.java:174)
at io.netty.util.concurrent.AbstractEventExecutor.safeExecute(AbstractEventExecutor.java:167)
at io.netty.util.concurrent.SingleThreadEventExecutor.runAllTasks(SingleThreadEventExecutor.java:470)
at io.netty.channel.nio.NioEventLoop.run(NioEventLoop.java:569)
at io.netty.util.concurrent.SingleThreadEventExecutor$4.run(SingleThreadEventExecutor.java:997)
at io.netty.util.internal.ThreadExecutorMap$2.run(ThreadExecutorMap.java:74)
at io.netty.util.concurrent.FastThreadLocalRunnable.run(FastThreadLocalRunnable.java:30)
at java.base/java.lang.Thread.run(Thread.java:833)
Caused by: io.netty.channel.ConnectTimeoutException: connection timed out: /192.168.0.244:4444
at io.netty.channel.nio.AbstractNioChannel$AbstractNioUnsafe$1.run(AbstractNioChannel.java:261)
... 10 more
]]>
    </failure>
  </testcase> <!-- test2 -->
</testsuite> <!-- Default test -->
